Workbook

Sheet About
A1: Market Intelligence & GTM Dashboard: software engineering services firms
A2: Public data from each firm's own homepage, accessed 2026-10-12. See Sources & Gaps.
A3: Blue text = sourced input. Black text = formula. Change an input and every metric updates.
A4: Wingman Partners itself is NOT in the dataset (its site could not be read). Recommendations are framed for a firm of its type.
A5: Years, team sizes, ratings and badges are the firms' own claims, not verified data.
A6: 'Not found' = not seen in the homepage text, not proven absent.
A7: Not collected: traffic, SEO, ads, LinkedIn activity, revenue, win rates. This is a public-homepage benchmark, not market research.

Sheet Dashboard
A1: Market Intelligence & GTM Dashboard (software engineering services)
A3: Select a brand: | B3: Simform
A5: Headline | B5: =INDEX(Brands!$C$2:$C$8,MATCH($B$3,Brands!$A$2:$A$8,0)) -> AI-Native Engineering For Digital Products & Enterprise Solutions
A6: Industries listed | B6: =INDEX(Metrics!$B$4:$B$10,MATCH($B$3,Metrics!$A$4:$A$10,0)) -> 5
A7: Engagement models named | B7: =INDEX(Metrics!$C$4:$C$10,MATCH($B$3,Metrics!$A$4:$A$10,0)) -> 1
A8: Publishes a rate | B8: =INDEX(Metrics!$H$4:$H$10,MATCH($B$3,Metrics!$A$4:$A$10,0)) -> No
A9: Content engine score (0-6) | B9: =INDEX(Metrics!$G$4:$G$10,MATCH($B$3,Metrics!$A$4:$A$10,0)) -> 6
A10: Partner badges | B10: =INDEX(Metrics!$E$4:$E$10,MATCH($B$3,Metrics!$A$4:$A$10,0)) -> 10
A11: Positioning themes used | B11: =SUM(INDEX(Positioning!$E$27:$K$34,0,MATCH($B$3,Positioning!$E$4:$K$4,0))) -> 4
A12: CTA types used | B12: =SUM(INDEX('CTA Funnel'!$E$23:$K$29,0,MATCH($B$3,'CTA Funnel'!$E$4:$K$4,0))) -> 3
A15: Market snapshot
A16: Brands compared | B16: ='GTM Plan'!B5 -> 7
A17: Headlines AI-led | B17: ='GTM Plan'!B6 -> 7
A18: Brands publishing a rate | B18: ='GTM Plan'!B8 -> 1
A19: Call / consult CTA | B19: ='GTM Plan'!B9 -> 5
A20: Whitepapers: Yes | B20: ='GTM Plan'!B15 -> 2

Sheet Brands
A1: brand | B1: homepage_url | C1: positioning_h1 | D1: positioning_sub | E1: vertical_focus | F1: industries | G1: engagement_models | H1: published_rate_text | I1: rate_low_usd_hr | J1: rate_high_usd_hr | K1: primary_ctas | L1: years_claimed | M1: team_claimed | N1: projects_claim_text | O1: rating_claim | P1: partner_badges | Q1: compliance_listed | R1: awards_mentioned | S1: case_studies | T1: blog | U1: whitepapers | V1: testimonials | W1: client_logos | X1: podcast_newsletter | Y1: confidence | Z1: notes | AA1: source_url | AB1: date_accessed
A2: Simform | B2: https://www.simform.com/ | C2: AI-Native Engineering For Digital Products & Enterprise Solutions | D2: Agile in mind, spirit, and speed | F2: Financial Services; Healthcare and Life Sciences; Retail and E-commerce; Supply Chain and Logistics; Hi-Tech and Digital Natives | G2: Services as Software (outcome-aligned commercials) | K2: Book a Consultation Call; Register Now; Call Us Now; Contact Us | N2: No company-level count on page; only per-client case-study figures (e.g. 'Serving over 1000 dealerships') | P2: Microsoft Azure Expert MSP; Microsoft Solutions Partner AI Business Solutions; Snowflake Select Tier; Microsoft Fabric Featured Partner; Anthropic Preferred Services Partner; Databricks Consulting Partner; IBM Silver Partner; AWS; Google Cloud; Advanced Datadog Partner | Q2: CMMI Level 3 | R2: Yes | S2: Yes | T2: Yes | U2: Yes | V2: Yes | W2: Yes | X2: Yes | Y2: High | Z2: Awards listed: Everest Group PEAK Matrix 2026; AIM Research PeMa Quadrant 2026. Also webinars, ebooks, podcast. | AA2: https://www.simform.com/ | AB2: 2026-10-12
A3: Appinventiv | B3: https://www.appinventiv.com/ | C3: Engineering the Next Generation of Digital Systems with AI | D3: Appinventiv engineers secure, scalable systems by combining architecture, data engineering, and AI | F3: Healthcare; Wearables; Fitness; On-Demand; Restaurant; Construction; Politics; eMobility; Logistics; Agriculture; Automotive; Finance; Entertainment; Education; Events; Manufacturing; Energy; OTT; Food Delivery; Supply Chain; Gaming; Ecommerce; Travel; Real Estate; Magazine & Newspaper; Social Media; Aviation; CSR; Retail; Telecom; Startup | G3: Dedicated Development Team; IT Outsourcing; Offshore Software Development; Managed IT Services | K3: Consult Our Strategy Team; Schedule Free Consultations; Book Your AI Advisory Session; Consult our Experts for Growth Roadmap; Discuss Your Technology Strategy; Contact Us | L3: 11 | M3: 1700 | N3: '3000+' Solutions; '150+' AI solutions; '35+' Industries | P3: OpenAI Select Partner; Claude Preferred Services Partner; AWS Advanced Tier Partner | Q3: GDPR; CCPA; HIPAA; ISO/IEC 27001; PCI DSS; NIST; FedRAMP; EU AI Act; ISO 9001; ISO 22301; ISO 14001; SOX; FTC Safeguards Rule; SOC 2; CSA Cloud Controls Matrix | R3: Yes | S3: Yes | T3: Yes | U3: Not found | V3: Yes | W3: Yes | X3: Not found | Y3: High | Z3: Page does not say whether the compliance items are certifications or frameworks worked within. Guides and press releases also exist. Team figure is labelled 'Technology Specialists'. | AA3: https://www.appinventiv.com/ | AB3: 2026-10-12
A4: Hyperlink InfoSystem | B4: https://www.hyperlinkinfosystem.com/ | C4: Building Tech Future With AI Innovation! | D4: Top Mobile Application development, Software Development & IT Consulting Company, Building Smart Solutions For A Smarter World. | F4: Education; Healthcare & Fitness; Fintech; Real Estate; Retail & eCommerce; Travel & Hospitality; Logistics & Distribution; Food & Restaurant; Gaming; Entertainment; On-Demand; Sports; Social Networking | G4: Fixed Price Model; Hire Dedicated Model (hourly rate); Onsite Model (contract basis) | K4: Get A Quote; Get A Free Quote; Book A Call; Schedule A Call; Hire Now; Hire Developers; Contact Us | L4: 14 | M4: 1200 | N4: '4500+' mobile apps; '2200+' websites; 'worked with 2700+ businesses' (a separate banner says '2000+ Businesses') | O4: 4.9 on Clutch.co (self-reported on own site) | P4: Google; Salesforce; AWS; Oracle | Q4: CMMI Level 3 | R4: Yes | S4: Yes | T4: Yes | U4: Yes | V4: Yes | W4: Yes | X4: Yes | Y4: High | Z4: Awards are '#1 Top App Development Company' badges (self-ranked, image-based). Founded 2011 per page. | AA4: https://www.hyperlinkinfosystem.com/ | AB4: 2026-10-12
A5: Space-O (healthcare site) | B5: https://www.spaceo.ai/ | C5: Healthcare Software Development Company for Custom Platforms and Practical AI | D5: Custom healthcare platforms for hospitals, clinics, health systems, and digital health startups. | E5: Healthcare | F5: Hospitals and Health Systems; Multi-Provider Clinics and Practice Groups; Digital Health Startups; Payers and RCM Companies | G5: Fixed-Scope Healthcare Projects (milestone-based payment, 20-50% upfront); Dedicated Healthcare Development Team (3-15 specialists); Staff Augmentation for Healthcare Engineering (custom pricing) | H5: '$25-49 per hour' (HIPAA compliance, EHR integration and AI capability); annual maintenance 15-25% of initial build cost | I5: 25 | J5: 49 | K5: Book a Discovery Call; View Our Portfolio; Hire EHR software developers; Hire patient portal developers; Read the review on Clutch | M5: 50 | N5: 'proven across 50+ healthcare projects since 2010' | O5: 'Clutch rates the team at 4.8 across 75 verified client reviews' (self-reported) | P5: OpenAI Select Partner; Claude Certified Architect; AWS | Q5: HIPAA; HL7 FHIR R4; GDPR; FDA; SOC 2 Type II | R5: Not found | S5: Yes | T5: Not found | U5: Not found | V5: Yes | W5: Yes | X5: Not found | Y5: Medium | Z5: Site calls itself 'Space-O'; the full name 'Space-O Technologies' is not on the page. Team figure is '50+ Healthcare Developers'. Only brand in the set that publishes a rate (seen on two fetches). | AA5: https://www.spaceo.ai/ | AB5: 2026-10-12
A6: Intellectsoft | B6: https://www.intellectsoft.net/ | C6: AI-First Software Engineering for Your Business Growth | D6: Fortune 500 enterprises and startups rely on the company's top 1% talent and AI-driven approach to design, build, and scale digital products. | F6: Construction; Retail & E-Commerce; Insurance; Transportation & Logistics; FinTech; Healthcare; Travel & Hospitality | G6: Dedicated Development Teams; Staff Augmentation; Team Extension; MVP Development; Outsourcing; Nearshore | K6: Estimate Now!; Get in touch; Book a 30-minutes intro call; Schedule a Call; Request an NDA; View case study | L6: 19 | N6: No client count; 12 client logos shown; 'Dedicated team assembled within 2 weeks'; 'reach the market 40% faster' | P6: AWS; Snowflake; Microsoft Certified Expert; Google Partner; Databricks | Q6: HIPAA Compliant; GDPR Compliant; ISO 9001:2015; ISO 27001 | R6: Not found | S6: Yes | T6: Yes | U6: Not found | V6: Yes | W6: Yes | X6: Not found | Y6: High | Z6: Years claim comes from the meta description ('19 years of experience'). Page says 'Mid-size by design'. News section exists. | AA6: https://www.intellectsoft.net/ | AB6: 2026-10-12
A7: Netguru | B7: https://www.netguru.com/ | C7: AI-native commerce | D7: We power digital commerce with AI-driven platforms, scalable marketplaces, and omnichannel experiences. | E7: Commerce (primary) | F7: Commerce; Finance and banking; Healthcare and life science; Education; Proptech | G7: Dedicated Teams; Staff Augmentation; Delivery Center | K7: Estimate project; Get in touch; More case studies | L7: 17 | M7: 400 | N7: '2500+' projects delivered; NPS '73' | O7: NPS 73 (self-reported) | P7: Microsoft; AWS; VTEX; Webflow Premium Partner | Q7: B-Corp; TUV NORD (logos only) | R7: Yes | S7: Yes | T7: Yes | U7: Not found | V7: Yes | W7: Yes | X7: Yes | Y7: Medium | Z7: CONFLICT on page: body says 17+ years and 400+ people; meta description says 'More than 10 years' and 'over 630 developers and designers'. Body figures used. Awards are logos only (Clutch, Inc. 5000, EY, Forbes). | AA7: https://www.netguru.com/ | AB7: 2026-10-12
A8: Thoughtworks | B8: https://www.thoughtworks.com/ | C8: We don't just do AI. We do AI that works | F8: Automotive; Public Sector; Energy; Media and Publishing; Retail and E-commerce; Financial Services; Not-for-profit; Travel and Transport; Utilities; Manufacturing and Engineering; Life Sciences and Medtech | K8: Explore AI/works; Explore our capabilities; View client work; Get in touch; Ask Tai | N8: No counts on page | P8: Microsoft; AWS; Google Cloud; Databricks; Snowflake | R8: Not found | S8: Partial | T8: Yes | U8: Partial | V8: Not found | W8: Partial | X8: Yes | Y8: Medium | Z8: Single fetch. No subheadline on page, so left blank. 'Client work' items exist but are not labelled case studies; reports and e-books exist; a logo image exists but names are not visible in text. 'Great Place to Work-Certified' shown. Much larger firm than the others. | AA8: https://www.thoughtworks.com/ | AB8: 2026-10-12

Sheet Sources & Gaps
A1: item | B1: what_happened | C1: how_handled
A2: Wingman Partners | B2: Own website is JavaScript-rendered; only the title 'Redefining Engineering Services' was readable. | C2: Company profile taken from a third-party listing (ZoomInfo: engineering services, 51-200 employees, unverified). Wingman is NOT in the dataset; recommendations are framed for a firm of its type.
A3: iMOBDEV | B3: Site disallows automated fetching (robots). | C3: Excluded. No workaround attempted.
A4: Fablian Technolab | B4: Domain redirected to a different site; could not confirm it is the same company. | C4: Excluded rather than guess.
A5: All brands | B5: Only homepages were read, via a page-fetch summarizer. | C5: 'Not found' means not seen in the homepage text, not proven absent. Spot-check quotes against live pages.
A6: All brands | B6: Core stats (years, team, ratings, CTAs) were fetched twice for 5 of 7 brands; Space-O rate fetched twice; Thoughtworks once. | C6: Confidence column reflects this.
A7: Pricing | B7: Only 1 of 7 brands publishes a rate. | C7: Pricing is analysed as a transparency gap, not a price comparison.
A8: Netguru | B8: Page contradicts itself (17+ vs 10+ years; 400+ vs 630 people). | C8: Body figures used; conflict recorded in notes.
A9: Appinventiv | B9: Page lists 15 compliance frameworks without saying whether certified. | C9: Stored as 'compliance listed', never counted as certifications.
A10: Claims | B10: Ratings, project counts, years and team sizes are the firms' own claims. | C10: Not verified market data.
A11: Thoughtworks | B11: No itemised services, engagement models or subheadline on homepage. | C11: Left blank.
A12: Not collected | B12: Traffic, SEO keywords, ad spend, LinkedIn activity, review-site content, win rates, revenue. | C12: Out of scope; this is a public-homepage benchmark.
A13: Themes | B13: Messaging themes are keyword matches on headline + subheadline (positioning), CTA text, and engagement-model text. | C13: Rules in src/themes.py, mirrored by Excel formulas.

Sheet Positioning
A1: Positioning themes (homepage headline + subheadline)
A2: Text is lower-cased, punctuation replaced by spaces, padded with spaces. 'word' = whole word, 'prefix' = word starts with keyword. Edit the blue keywords to re-run.
A4: Theme | B4: Keyword | C4: Match | D4: Search needle | E4: Simform | F4: Appinventiv | G4: Hyperlink InfoSystem | H4: Space-O (healthcare site) | I4: Intellectsoft | J4: Netguru | K4: Thoughtworks
A5: Normalised text | E5: =" "&SUBSTITUTE(SUBSTITUTE(SUBSTITUTE(SUBSTITUTE(SUBSTITUTE(SUBSTITUTE(SUBSTITUTE(SUBSTITUTE(SUBSTITUTE(SUBSTITUTE(SUBSTITUTE(SUBSTITUTE(SUBSTITUTE(SUBSTITUTE(SUBSTITUTE(SUBSTITUTE(LOWER(Brands!$C$2&" "&Brands!$D$2),"-"," "),"."," "),","," "),":"," "),";"," "),"!"," "),"?"," "),"'"," "),""""," "),"’"," "),"—"," "),"/"," "),"("," "),")"," "),"&"," "),"+"," ")&" " -> ai native engineering for digital products enterprise solutions agile in mind spirit and speed | F5: =" "&SUBSTITUTE(SUBSTITUTE(SUBSTITUTE(SUBSTITUTE(SUBSTITUTE(SUBSTITUTE(SUBSTITUTE(SUBSTITUTE(SUBSTITUTE(SUBSTITUTE(SUBSTITUTE(SUBSTITUTE(SUBSTITUTE(SUBSTITUTE(SUBSTITUTE(SUBSTITUTE(LOWER(Brands!$C$3&" "&Brands!$D$3),"-"," "),"."," "),","," "),":"," "),";"," "),"!"," "),"?"," "),"'"," "),""""," "),"’"," "),"—"," "),"/"," "),"("," "),")"," "),"&"," "),"+"," ")&" " -> engineering the next generation of digital systems with ai appinventiv engineers secure scalable systems by combining architecture data engineering and ai | G5: =" "&SUBSTITUTE(SUBSTITUTE(SUBSTITUTE(SUBSTITUTE(SUBSTITUTE(SUBSTITUTE(SUBSTITUTE(SUBSTITUTE(SUBSTITUTE(SUBSTITUTE(SUBSTITUTE(SUBSTITUTE(SUBSTITUTE(SUBSTITUTE(SUBSTITUTE(SUBSTITUTE(LOWER(Brands!$C$4&" "&Brands!$D$4),"-"," "),"."," "),","," "),":"," "),";"," "),"!"," "),"?"," "),"'"," "),""""," "),"’"," "),"—"," "),"/"," "),"("," "),")"," "),"&"," "),"+"," ")&" " -> building tech future with ai innovation top mobile application development software development it consulting company building smart solutions for a smarter world | H5: =" "&SUBSTITUTE(SUBSTITUTE(SUBSTITUTE(SUBSTITUTE(SUBSTITUTE(SUBSTITUTE(SUBSTITUTE(SUBSTITUTE(SUBSTITUTE(SUBSTITUTE(SUBSTITUTE(SUBSTITUTE(SUBSTITUTE(SUBSTITUTE(SUBSTITUTE(SUBSTITUTE(LOWER(Brands!$C$5&" "&Brands!$D$5),"-"," "),"."," "),","," "),":"," "),";"," "),"!"," "),"?"," "),"'"," "),""""," "),"’"," "),"—"," "),"/"," "),"("," "),")"," "),"&"," "),"+"," ")&" " -> healthcare software development company for custom platforms and practical ai custom healthcare platforms for hospitals clinics health systems and digital health startups | I5: =" "&SUBSTITUTE(SUBSTITUTE(SUBSTITUTE(SUBSTITUTE(SUBSTITUTE(SUBSTITUTE(SUBSTITUTE(SUBSTITUTE(SUBSTITUTE(SUBSTITUTE(SUBSTITUTE(SUBSTITUTE(SUBSTITUTE(SUBSTITUTE(SUBSTITUTE(SUBSTITUTE(LOWER(Brands!$C$6&" "&Brands!$D$6),"-"," "),"."," "),","," "),":"," "),";"," "),"!"," "),"?"," "),"'"," "),""""," "),"’"," "),"—"," "),"/"," "),"("," "),")"," "),"&"," "),"+"," ")&" " -> ai first software engineering for your business growth fortune 500 enterprises and startups rely on the company s top 1% talent and ai driven approach to design build and scale digital products | J5: =" "&SUBSTITUTE(SUBSTITUTE(SUBSTITUTE(SUBSTITUTE(SUBSTITUTE(SUBSTITUTE(SUBSTITUTE(SUBSTITUTE(SUBSTITUTE(SUBSTITUTE(SUBSTITUTE(SUBSTITUTE(SUBSTITUTE(SUBSTITUTE(SUBSTITUTE(SUBSTITUTE(LOWER(Brands!$C$7&" "&Brands!$D$7),"-"," "),"."," "),","," "),":"," "),";"," "),"!"," "),"?"," "),"'"," "),""""," "),"’"," "),"—"," "),"/"," "),"("," "),")"," "),"&"," "),"+"," ")&" " -> ai native commerce we power digital commerce with ai driven platforms scalable marketplaces and omnichannel experiences | K5: =" "&SUBSTITUTE(SUBSTITUTE(SUBSTITUTE(SUBSTITUTE(SUBSTITUTE(SUBSTITUTE(SUBSTITUTE(SUBSTITUTE(SUBSTITUTE(SUBSTITUTE(SUBSTITUTE(SUBSTITUTE(SUBSTITUTE(SUBSTITUTE(SUBSTITUTE(SUBSTITUTE(LOWER(Brands!$C$8&" "&Brands!$D$8),"-"," "),"."," "),","," "),":"," "),";"," "),"!"," "),"?"," "),"'"," "),""""," "),"’"," "),"—"," "),"/"," "),"("," "),")"," "),"&"," "),"+"," ")&" " -> we don t just do ai we do ai that works
A6: AI-led | B6: ai | C6: word | D6: =" "&B6&IF(C6="word"," ","") -> ai | E6: =IF(B6="",0,IF(ISNUMBER(FIND($D6,E$5)),1,0)) -> 1 | F6: =IF(B6="",0,IF(ISNUMBER(FIND($D6,F$5)),1,0)) -> 1 | G6: =IF(B6="",0,IF(ISNUMBER(FIND($D6,G$5)),1,0)) -> 1 | H6: =IF(B6="",0,IF(ISNUMBER(FIND($D6,H$5)),1,0)) -> 1 | I6: =IF(B6="",0,IF(ISNUMBER(FIND($D6,I$5)),1,0)) -> 1 | J6: =IF(B6="",0,IF(ISNUMBER(FIND($D6,J$5)),1,0)) -> 1 | K6: =IF(B6="",0,IF(ISNUMBER(FIND($D6,K$5)),1,0)) -> 1
A7: AI-led | B7: agent | C7: prefix | D7: =" "&B7&IF(C7="word"," ","") -> agent | E7: =IF(B7="",0,IF(ISNUMBER(FIND($D7,E$5)),1,0)) -> 0 | F7: =IF(B7="",0,IF(ISNUMBER(FIND($D7,F$5)),1,0)) -> 0 | G7: =IF(B7="",0,IF(ISNUMBER(FIND($D7,G$5)),1,0)) -> 0 | H7: =IF(B7="",0,IF(ISNUMBER(FIND($D7,H$5)),1,0)) -> 0 | I7: =IF(B7="",0,IF(ISNUMBER(FIND($D7,I$5)),1,0)) -> 0 | J7: =IF(B7="",0,IF(ISNUMBER(FIND($D7,J$5)),1,0)) -> 0 | K7: =IF(B7="",0,IF(ISNUMBER(FIND($D7,K$5)),1,0)) -> 0
A8: Engineering craft | B8: engineering | C8: word | D8: =" "&B8&IF(C8="word"," ","") -> engineering | E8: =IF(B8="",0,IF(ISNUMBER(FIND($D8,E$5)),1,0)) -> 1 | F8: =IF(B8="",0,IF(ISNUMBER(FIND($D8,F$5)),1,0)) -> 1 | G8: =IF(B8="",0,IF(ISNUMBER(FIND($D8,G$5)),1,0)) -> 0 | H8: =IF(B8="",0,IF(ISNUMBER(FIND($D8,H$5)),1,0)) -> 0 | I8: =IF(B8="",0,IF(ISNUMBER(FIND($D8,I$5)),1,0)) -> 1 | J8: =IF(B8="",0,IF(ISNUMBER(FIND($D8,J$5)),1,0)) -> 0 | K8: =IF(B8="",0,IF(ISNUMBER(FIND($D8,K$5)),1,0)) -> 0
A9: Engineering craft | B9: engineers | C9: word | D9: =" "&B9&IF(C9="word"," ","") -> engineers | E9: =IF(B9="",0,IF(ISNUMBER(FIND($D9,E$5)),1,0)) -> 0 | F9: =IF(B9="",0,IF(ISNUMBER(FIND($D9,F$5)),1,0)) -> 1 | G9: =IF(B9="",0,IF(ISNUMBER(FIND($D9,G$5)),1,0)) -> 0 | H9: =IF(B9="",0,IF(ISNUMBER(FIND($D9,H$5)),1,0)) -> 0 | I9: =IF(B9="",0,IF(ISNUMBER(FIND($D9,I$5)),1,0)) -> 0 | J9: =IF(B9="",0,IF(ISNUMBER(FIND($D9,J$5)),1,0)) -> 0 | K9: =IF(B9="",0,IF(ISNUMBER(FIND($D9,K$5)),1,0)) -> 0
A10: Speed & agility | B10: agile | C10: word | D10: =" "&B10&IF(C10="word"," ","") -> agile | E10: =IF(B10="",0,IF(ISNUMBER(FIND($D10,E$5)),1,0)) -> 1 | F10: =IF(B10="",0,IF(ISNUMBER(FIND($D10,F$5)),1,0)) -> 0 | G10: =IF(B10="",0,IF(ISNUMBER(FIND($D10,G$5)),1,0)) -> 0 | H10: =IF(B10="",0,IF(ISNUMBER(FIND($D10,H$5)),1,0)) -> 0 | I10: =IF(B10="",0,IF(ISNUMBER(FIND($D10,I$5)),1,0)) -> 0 | J10: =IF(B10="",0,IF(ISNUMBER(FIND($D10,J$5)),1,0)) -> 0 | K10: =IF(B10="",0,IF(ISNUMBER(FIND($D10,K$5)),1,0)) -> 0
A11: Speed & agility | B11: speed | C11: word | D11: =" "&B11&IF(C11="word"," ","") -> speed | E11: =IF(B11="",0,IF(ISNUMBER(FIND($D11,E$5)),1,0)) -> 1 | F11: =IF(B11="",0,IF(ISNUMBER(FIND($D11,F$5)),1,0)) -> 0 | G11: =IF(B11="",0,IF(ISNUMBER(FIND($D11,G$5)),1,0)) -> 0 | H11: =IF(B11="",0,IF(ISNUMBER(FIND($D11,H$5)),1,0)) -> 0 | I11: =IF(B11="",0,IF(ISNUMBER(FIND($D11,I$5)),1,0)) -> 0 | J11: =IF(B11="",0,IF(ISNUMBER(FIND($D11,J$5)),1,0)) -> 0 | K11: =IF(B11="",0,IF(ISNUMBER(FIND($D11,K$5)),1,0)) -> 0
A12: Speed & agility | B12: faster | C12: word | D12: =" "&B12&IF(C12="word"," ","") -> faster | E12: =IF(B12="",0,IF(ISNUMBER(FIND($D12,E$5)),1,0)) -> 0 | F12: =IF(B12="",0,IF(ISNUMBER(FIND($D12,F$5)),1,0)) -> 0 | G12: =IF(B12="",0,IF(ISNUMBER(FIND($D12,G$5)),1,0)) -> 0 | H12: =IF(B12="",0,IF(ISNUMBER(FIND($D12,H$5)),1,0)) -> 0 | I12: =IF(B12="",0,IF(ISNUMBER(FIND($D12,I$5)),1,0)) -> 0 | J12: =IF(B12="",0,IF(ISNUMBER(FIND($D12,J$5)),1,0)) -> 0 | K12: =IF(B12="",0,IF(ISNUMBER(FIND($D12,K$5)),1,0)) -> 0
A13: Scale & security | B13: scal | C13: prefix | D13: =" "&B13&IF(C13="word"," ","") -> scal | E13: =IF(B13="",0,IF(ISNUMBER(FIND($D13,E$5)),1,0)) -> 0 | F13: =IF(B13="",0,IF(ISNUMBER(FIND($D13,F$5)),1,0)) -> 1 | G13: =IF(B13="",0,IF(ISNUMBER(FIND($D13,G$5)),1,0)) -> 0 | H13: =IF(B13="",0,IF(ISNUMBER(FIND($D13,H$5)),1,0)) -> 0 | I13: =IF(B13="",0,IF(ISNUMBER(FIND($D13,I$5)),1,0)) -> 1 | J13: =IF(B13="",0,IF(ISNUMBER(FIND($D13,J$5)),1,0)) -> 1 | K13: =IF(B13="",0,IF(ISNUMBER(FIND($D13,K$5)),1,0)) -> 0
A14: Scale & security | B14: secure | C14: prefix | D14: =" "&B14&IF(C14="word"," ","") -> secure | E14: =IF(B14="",0,IF(ISNUMBER(FIND($D14,E$5)),1,0)) -> 0 | F14: =IF(B14="",0,IF(ISNUMBER(FIND($D14,F$5)),1,0)) -> 1 | G14: =IF(B14="",0,IF(ISNUMBER(FIND($D14,G$5)),1,0)) -> 0 | H14: =IF(B14="",0,IF(ISNUMBER(FIND($D14,H$5)),1,0)) -> 0 | I14: =IF(B14="",0,IF(ISNUMBER(FIND($D14,I$5)),1,0)) -> 0 | J14: =IF(B14="",0,IF(ISNUMBER(FIND($D14,J$5)),1,0)) -> 0 | K14: =IF(B14="",0,IF(ISNUMBER(FIND($D14,K$5)),1,0)) -> 0
A15: Business growth | B15: growth | C15: word | D15: =" "&B15&IF(C15="word"," ","") -> growth | E15: =IF(B15="",0,IF(ISNUMBER(FIND($D15,E$5)),1,0)) -> 0 | F15: =IF(B15="",0,IF(ISNUMBER(FIND($D15,F$5)),1,0)) -> 0 | G15: =IF(B15="",0,IF(ISNUMBER(FIND($D15,G$5)),1,0)) -> 0 | H15: =IF(B15="",0,IF(ISNUMBER(FIND($D15,H$5)),1,0)) -> 0 | I15: =IF(B15="",0,IF(ISNUMBER(FIND($D15,I$5)),1,0)) -> 1 | J15: =IF(B15="",0,IF(ISNUMBER(FIND($D15,J$5)),1,0)) -> 0 | K15: =IF(B15="",0,IF(ISNUMBER(FIND($D15,K$5)),1,0)) -> 0
A16: Business growth | B16: business | C16: word | D16: =" "&B16&IF(C16="word"," ","") -> business | E16: =IF(B16="",0,IF(ISNUMBER(FIND($D16,E$5)),1,0)) -> 0 | F16: =IF(B16="",0,IF(ISNUMBER(FIND($D16,F$5)),1,0)) -> 0 | G16: =IF(B16="",0,IF(ISNUMBER(FIND($D16,G$5)),1,0)) -> 0 | H16: =IF(B16="",0,IF(ISNUMBER(FIND($D16,H$5)),1,0)) -> 0 | I16: =IF(B16="",0,IF(ISNUMBER(FIND($D16,I$5)),1,0)) -> 1 | J16: =IF(B16="",0,IF(ISNUMBER(FIND($D16,J$5)),1,0)) -> 0 | K16: =IF(B16="",0,IF(ISNUMBER(FIND($D16,K$5)),1,0)) -> 0
A17: Vertical focus | B17: healthcare | C17: word | D17: =" "&B17&IF(C17="word"," ","") -> healthcare | E17: =IF(B17="",0,IF(ISNUMBER(FIND($D17,E$5)),1,0)) -> 0 | F17: =IF(B17="",0,IF(ISNUMBER(FIND($D17,F$5)),1,0)) -> 0 | G17: =IF(B17="",0,IF(ISNUMBER(FIND($D17,G$5)),1,0)) -> 0 | H17: =IF(B17="",0,IF(ISNUMBER(FIND($D17,H$5)),1,0)) -> 1 | I17: =IF(B17="",0,IF(ISNUMBER(FIND($D17,I$5)),1,0)) -> 0 | J17: =IF(B17="",0,IF(ISNUMBER(FIND($D17,J$5)),1,0)) -> 0 | K17: =IF(B17="",0,IF(ISNUMBER(FIND($D17,K$5)),1,0)) -> 0
... A24: Credibility claim | B24: top 1 | C24: prefix | D24: =" "&B24&IF(C24="word"," ","") -> top 1 | E24: =IF(B24="",0,IF(ISNUMBER(FIND($D24,E$5)),1,0)) -> 0 | F24: =IF(B24="",0,IF(ISNUMBER(FIND($D24,F$5)),1,0)) -> 0 | G24: =IF(B24="",0,IF(ISNUMBER(FIND($D24,G$5)),1,0)) -> 0 | H24: =IF(B24="",0,IF(ISNUMBER(FIND($D24,H$5)),1,0)) -> 0 | I24: =IF(B24="",0,IF(ISNUMBER(FIND($D24,I$5)),1,0)) -> 1 | J24: =IF(B24="",0,IF(ISNUMBER(FIND($D24,J$5)),1,0)) -> 0 | K24: =IF(B24="",0,IF(ISNUMBER(FIND($D24,K$5)),1,0)) -> 0
A26: Theme summary (1 = present) | D26: Brands using | E26: Simform | F26: Appinventiv | G26: Hyperlink InfoSystem | H26: Space-O (healthcare site) | I26: Intellectsoft | J26: Netguru | K26: Thoughtworks
A27: AI-led | D27: =SUM(E27:K27) -> 7 | E27: =IF(SUMIF($A$6:$A$24,$A27,E$6:E$24)>0,1,0) -> 1 | F27: =IF(SUMIF($A$6:$A$24,$A27,F$6:F$24)>0,1,0) -> 1 | G27: =IF(SUMIF($A$6:$A$24,$A27,G$6:G$24)>0,1,0) -> 1 | H27: =IF(SUMIF($A$6:$A$24,$A27,H$6:H$24)>0,1,0) -> 1 | I27: =IF(SUMIF($A$6:$A$24,$A27,I$6:I$24)>0,1,0) -> 1 | J27: =IF(SUMIF($A$6:$A$24,$A27,J$6:J$24)>0,1,0) -> 1 | K27: =IF(SUMIF($A$6:$A$24,$A27,K$6:K$24)>0,1,0) -> 1
A28: Engineering craft | D28: =SUM(E28:K28) -> 3 | E28: =IF(SUMIF($A$6:$A$24,$A28,E$6:E$24)>0,1,0) -> 1 | F28: =IF(SUMIF($A$6:$A$24,$A28,F$6:F$24)>0,1,0) -> 1 | G28: =IF(SUMIF($A$6:$A$24,$A28,G$6:G$24)>0,1,0) -> 0 | H28: =IF(SUMIF($A$6:$A$24,$A28,H$6:H$24)>0,1,0) -> 0 | I28: =IF(SUMIF($A$6:$A$24,$A28,I$6:I$24)>0,1,0) -> 1 | J28: =IF(SUMIF($A$6:$A$24,$A28,J$6:J$24)>0,1,0) -> 0 | K28: =IF(SUMIF($A$6:$A$24,$A28,K$6:K$24)>0,1,0) -> 0
A29: Speed & agility | D29: =SUM(E29:K29) -> 1 | E29: =IF(SUMIF($A$6:$A$24,$A29,E$6:E$24)>0,1,0) -> 1 | F29: =IF(SUMIF($A$6:$A$24,$A29,F$6:F$24)>0,1,0) -> 0 | G29: =IF(SUMIF($A$6:$A$24,$A29,G$6:G$24)>0,1,0) -> 0 | H29: =IF(SUMIF($A$6:$A$24,$A29,H$6:H$24)>0,1,0) -> 0 | I29: =IF(SUMIF($A$6:$A$24,$A29,I$6:I$24)>0,1,0) -> 0 | J29: =IF(SUMIF($A$6:$A$24,$A29,J$6:J$24)>0,1,0) -> 0 | K29: =IF(SUMIF($A$6:$A$24,$A29,K$6:K$24)>0,1,0) -> 0
A30: Scale & security | D30: =SUM(E30:K30) -> 3 | E30: =IF(SUMIF($A$6:$A$24,$A30,E$6:E$24)>0,1,0) -> 0 | F30: =IF(SUMIF($A$6:$A$24,$A30,F$6:F$24)>0,1,0) -> 1 | G30: =IF(SUMIF($A$6:$A$24,$A30,G$6:G$24)>0,1,0) -> 0 | H30: =IF(SUMIF($A$6:$A$24,$A30,H$6:H$24)>0,1,0) -> 0 | I30: =IF(SUMIF($A$6:$A$24,$A30,I$6:I$24)>0,1,0) -> 1 | J30: =IF(SUMIF($A$6:$A$24,$A30,J$6:J$24)>0,1,0) -> 1 | K30: =IF(SUMIF($A$6:$A$24,$A30,K$6:K$24)>0,1,0) -> 0
A31: Business growth | D31: =SUM(E31:K31) -> 1 | E31: =IF(SUMIF($A$6:$A$24,$A31,E$6:E$24)>0,1,0) -> 0 | F31: =IF(SUMIF($A$6:$A$24,$A31,F$6:F$24)>0,1,0) -> 0 | G31: =IF(SUMIF($A$6:$A$24,$A31,G$6:G$24)>0,1,0) -> 0 | H31: =IF(SUMIF($A$6:$A$24,$A31,H$6:H$24)>0,1,0) -> 0 | I31: =IF(SUMIF($A$6:$A$24,$A31,I$6:I$24)>0,1,0) -> 1 | J31: =IF(SUMIF($A$6:$A$24,$A31,J$6:J$24)>0,1,0) -> 0 | K31: =IF(SUMIF($A$6:$A$24,$A31,K$6:K$24)>0,1,0) -> 0
A32: Vertical focus | D32: =SUM(E32:K32) -> 2 | E32: =IF(SUMIF($A$6:$A$24,$A32,E$6:E$24)>0,1,0) -> 0 | F32: =IF(SUMIF($A$6:$A$24,$A32,F$6:F$24)>0,1,0) -> 0 | G32: =IF(SUMIF($A$6:$A$24,$A32,G$6:G$24)>0,1,0) -> 0 | H32: =IF(SUMIF($A$6:$A$24,$A32,H$6:H$24)>0,1,0) -> 1 | I32: =IF(SUMIF($A$6:$A$24,$A32,I$6:I$24)>0,1,0) -> 0 | J32: =IF(SUMIF($A$6:$A$24,$A32,J$6:J$24)>0,1,0) -> 1 | K32: =IF(SUMIF($A$6:$A$24,$A32,K$6:K$24)>0,1,0) -> 0
A33: Product / digital | D33: =SUM(E33:K33) -> 5 | E33: =IF(SUMIF($A$6:$A$24,$A33,E$6:E$24)>0,1,0) -> 1 | F33: =IF(SUMIF($A$6:$A$24,$A33,F$6:F$24)>0,1,0) -> 1 | G33: =IF(SUMIF($A$6:$A$24,$A33,G$6:G$24)>0,1,0) -> 0 | H33: =IF(SUMIF($A$6:$A$24,$A33,H$6:H$24)>0,1,0) -> 1 | I33: =IF(SUMIF($A$6:$A$24,$A33,I$6:I$24)>0,1,0) -> 1 | J33: =IF(SUMIF($A$6:$A$24,$A33,J$6:J$24)>0,1,0) -> 1 | K33: =IF(SUMIF($A$6:$A$24,$A33,K$6:K$24)>0,1,0) -> 0
A34: Credibility claim | D34: =SUM(E34:K34) -> 1 | E34: =IF(SUMIF($A$6:$A$24,$A34,E$6:E$24)>0,1,0) -> 0 | F34: =IF(SUMIF($A$6:$A$24,$A34,F$6:F$24)>0,1,0) -> 0 | G34: =IF(SUMIF($A$6:$A$24,$A34,G$6:G$24)>0,1,0) -> 0 | H34: =IF(SUMIF($A$6:$A$24,$A34,H$6:H$24)>0,1,0) -> 0 | I34: =IF(SUMIF($A$6:$A$24,$A34,I$6:I$24)>0,1,0) -> 1 | J34: =IF(SUMIF($A$6:$A$24,$A34,J$6:J$24)>0,1,0) -> 0 | K34: =IF(SUMIF($A$6:$A$24,$A34,K$6:K$24)>0,1,0) -> 0

Sheet CTA Funnel
A1: Lead-capture CTAs (primary calls to action on the homepage)
A2: Text is lower-cased, punctuation replaced by spaces, padded with spaces. 'word' = whole word, 'prefix' = word starts with keyword. Edit the blue keywords to re-run.
A4: Theme | B4: Keyword | C4: Match | D4: Search needle | E4: Simform | F4: Appinventiv | G4: Hyperlink InfoSystem | H4: Space-O (healthcare site) | I4: Intellectsoft | J4: Netguru | K4: Thoughtworks
A5: Normalised text | E5: =" "&SUBSTITUTE(SUBSTITUTE(SUBSTITUTE(SUBSTITUTE(SUBSTITUTE(SUBSTITUTE(SUBSTITUTE(SUBSTITUTE(SUBSTITUTE(SUBSTITUTE(SUBSTITUTE(SUBSTITUTE(SUBSTITUTE(SUBSTITUTE(SUBSTITUTE(SUBSTITUTE(LOWER(Brands!$K$2),"-"," "),"."," "),","," "),":"," "),";"," "),"!"," "),"?"," "),"'"," "),""""," "),"’"," "),"—"," "),"/"," "),"("," "),")"," "),"&"," "),"+"," ")&" " -> book a consultation call register now call us now contact us | F5: =" "&SUBSTITUTE(SUBSTITUTE(SUBSTITUTE(SUBSTITUTE(SUBSTITUTE(SUBSTITUTE(SUBSTITUTE(SUBSTITUTE(SUBSTITUTE(SUBSTITUTE(SUBSTITUTE(SUBSTITUTE(SUBSTITUTE(SUBSTITUTE(SUBSTITUTE(SUBSTITUTE(LOWER(Brands!$K$3),"-"," "),"."," "),","," "),":"," "),";"," "),"!"," "),"?"," "),"'"," "),""""," "),"’"," "),"—"," "),"/"," "),"("," "),")"," "),"&"," "),"+"," ")&" " -> consult our strategy team schedule free consultations book your ai advisory session consult our experts for growth roadmap discuss your technology strategy contact us | G5: =" "&SUBSTITUTE(SUBSTITUTE(SUBSTITUTE(SUBSTITUTE(SUBSTITUTE(SUBSTITUTE(SUBSTITUTE(SUBSTITUTE(SUBSTITUTE(SUBSTITUTE(SUBSTITUTE(SUBSTITUTE(SUBSTITUTE(SUBSTITUTE(SUBSTITUTE(SUBSTITUTE(LOWER(Brands!$K$4),"-"," "),"."," "),","," "),":"," "),";"," "),"!"," "),"?"," "),"'"," "),""""," "),"’"," "),"—"," "),"/"," "),"("," "),")"," "),"&"," "),"+"," ")&" " -> get a quote get a free quote book a call schedule a call hire now hire developers contact us | H5: =" "&SUBSTITUTE(SUBSTITUTE(SUBSTITUTE(SUBSTITUTE(SUBSTITUTE(SUBSTITUTE(SUBSTITUTE(SUBSTITUTE(SUBSTITUTE(SUBSTITUTE(SUBSTITUTE(SUBSTITUTE(SUBSTITUTE(SUBSTITUTE(SUBSTITUTE(SUBSTITUTE(LOWER(Brands!$K$5),"-"," "),"."," "),","," "),":"," "),";"," "),"!"," "),"?"," "),"'"," "),""""," "),"’"," "),"—"," "),"/"," "),"("," "),")"," "),"&"," "),"+"," ")&" " -> book a discovery call view our portfolio hire ehr software developers hire patient portal developers read the review on clutch | I5: =" "&SUBSTITUTE(SUBSTITUTE(SUBSTITUTE(SUBSTITUTE(SUBSTITUTE(SUBSTITUTE(SUBSTITUTE(SUBSTITUTE(SUBSTITUTE(SUBSTITUTE(SUBSTITUTE(SUBSTITUTE(SUBSTITUTE(SUBSTITUTE(SUBSTITUTE(SUBSTITUTE(LOWER(Brands!$K$6),"-"," "),"."," "),","," "),":"," "),";"," "),"!"," "),"?"," "),"'"," "),""""," "),"’"," "),"—"," "),"/"," "),"("," "),")"," "),"&"," "),"+"," ")&" " -> estimate now get in touch book a 30 minutes intro call schedule a call request an nda view case study | J5: =" "&SUBSTITUTE(SUBSTITUTE(SUBSTITUTE(SUBSTITUTE(SUBSTITUTE(SUBSTITUTE(SUBSTITUTE(SUBSTITUTE(SUBSTITUTE(SUBSTITUTE(SUBSTITUTE(SUBSTITUTE(SUBSTITUTE(SUBSTITUTE(SUBSTITUTE(SUBSTITUTE(LOWER(Brands!$K$7),"-"," "),"."," "),","," "),":"," "),";"," "),"!"," "),"?"," "),"'"," "),""""," "),"’"," "),"—"," "),"/"," "),"("," "),")"," "),"&"," "),"+"," ")&" " -> estimate project get in touch more case studies | K5: =" "&SUBSTITUTE(SUBSTITUTE(SUBSTITUTE(SUBSTITUTE(SUBSTITUTE(SUBSTITUTE(SUBSTITUTE(SUBSTITUTE(SUBSTITUTE(SUBSTITUTE(SUBSTITUTE(SUBSTITUTE(SUBSTITUTE(SUBSTITUTE(SUBSTITUTE(SUBSTITUTE(LOWER(Brands!$K$8),"-"," "),"."," "),","," "),":"," "),";"," "),"!"," "),"?"," "),"'"," "),""""," "),"’"," "),"—"," "),"/"," "),"("," "),")"," "),"&"," "),"+"," ")&" " -> explore ai works explore our capabilities view client work get in touch ask tai
A6: Book a call / consult | B6: call | C6: word | D6: =" "&B6&IF(C6="word"," ","") -> call | E6: =IF(B6="",0,IF(ISNUMBER(FIND($D6,E$5)),1,0)) -> 1 | F6: =IF(B6="",0,IF(ISNUMBER(FIND($D6,F$5)),1,0)) -> 0 | G6: =IF(B6="",0,IF(ISNUMBER(FIND($D6,G$5)),1,0)) -> 1 | H6: =IF(B6="",0,IF(ISNUMBER(FIND($D6,H$5)),1,0)) -> 1 | I6: =IF(B6="",0,IF(ISNUMBER(FIND($D6,I$5)),1,0)) -> 1 | J6: =IF(B6="",0,IF(ISNUMBER(FIND($D6,J$5)),1,0)) -> 0 | K6: =IF(B6="",0,IF(ISNUMBER(FIND($D6,K$5)),1,0)) -> 0
A7: Book a call / consult | B7: consult | C7: prefix | D7: =" "&B7&IF(C7="word"," ","") -> consult | E7: =IF(B7="",0,IF(ISNUMBER(FIND($D7,E$5)),1,0)) -> 1 | F7: =IF(B7="",0,IF(ISNUMBER(FIND($D7,F$5)),1,0)) -> 1 | G7: =IF(B7="",0,IF(ISNUMBER(FIND($D7,G$5)),1,0)) -> 0 | H7: =IF(B7="",0,IF(ISNUMBER(FIND($D7,H$5)),1,0)) -> 0 | I7: =IF(B7="",0,IF(ISNUMBER(FIND($D7,I$5)),1,0)) -> 0 | J7: =IF(B7="",0,IF(ISNUMBER(FIND($D7,J$5)),1,0)) -> 0 | K7: =IF(B7="",0,IF(ISNUMBER(FIND($D7,K$5)),1,0)) -> 0
A8: Book a call / consult | B8: discovery | C8: word | D8: =" "&B8&IF(C8="word"," ","") -> discovery | E8: =IF(B8="",0,IF(ISNUMBER(FIND($D8,E$5)),1,0)) -> 0 | F8: =IF(B8="",0,IF(ISNUMBER(FIND($D8,F$5)),1,0)) -> 0 | G8: =IF(B8="",0,IF(ISNUMBER(FIND($D8,G$5)),1,0)) -> 0 | H8: =IF(B8="",0,IF(ISNUMBER(FIND($D8,H$5)),1,0)) -> 1 | I8: =IF(B8="",0,IF(ISNUMBER(FIND($D8,I$5)),1,0)) -> 0 | J8: =IF(B8="",0,IF(ISNUMBER(FIND($D8,J$5)),1,0)) -> 0 | K8: =IF(B8="",0,IF(ISNUMBER(FIND($D8,K$5)),1,0)) -> 0
A9: Book a call / consult | B9: intro | C9: word | D9: =" "&B9&IF(C9="word"," ","") -> intro | E9: =IF(B9="",0,IF(ISNUMBER(FIND($D9,E$5)),1,0)) -> 0 | F9: =IF(B9="",0,IF(ISNUMBER(FIND($D9,F$5)),1,0)) -> 0 | G9: =IF(B9="",0,IF(ISNUMBER(FIND($D9,G$5)),1,0)) -> 0 | H9: =IF(B9="",0,IF(ISNUMBER(FIND($D9,H$5)),1,0)) -> 0 | I9: =IF(B9="",0,IF(ISNUMBER(FIND($D9,I$5)),1,0)) -> 1 | J9: =IF(B9="",0,IF(ISNUMBER(FIND($D9,J$5)),1,0)) -> 0 | K9: =IF(B9="",0,IF(ISNUMBER(FIND($D9,K$5)),1,0)) -> 0
A10: Get a quote / estimate | B10: quote | C10: word | D10: =" "&B10&IF(C10="word"," ","") -> quote | E10: =IF(B10="",0,IF(ISNUMBER(FIND($D10,E$5)),1,0)) -> 0 | F10: =IF(B10="",0,IF(ISNUMBER(FIND($D10,F$5)),1,0)) -> 0 | G10: =IF(B10="",0,IF(ISNUMBER(FIND($D10,G$5)),1,0)) -> 1 | H10: =IF(B10="",0,IF(ISNUMBER(FIND($D10,H$5)),1,0)) -> 0 | I10: =IF(B10="",0,IF(ISNUMBER(FIND($D10,I$5)),1,0)) -> 0 | J10: =IF(B10="",0,IF(ISNUMBER(FIND($D10,J$5)),1,0)) -> 0 | K10: =IF(B10="",0,IF(ISNUMBER(FIND($D10,K$5)),1,0)) -> 0
A11: Get a quote / estimate | B11: estimate | C11: prefix | D11: =" "&B11&IF(C11="word"," ","") -> estimate | E11: =IF(B11="",0,IF(ISNUMBER(FIND($D11,E$5)),1,0)) -> 0 | F11: =IF(B11="",0,IF(ISNUMBER(FIND($D11,F$5)),1,0)) -> 0 | G11: =IF(B11="",0,IF(ISNUMBER(FIND($D11,G$5)),1,0)) -> 0 | H11: =IF(B11="",0,IF(ISNUMBER(FIND($D11,H$5)),1,0)) -> 0 | I11: =IF(B11="",0,IF(ISNUMBER(FIND($D11,I$5)),1,0)) -> 1 | J11: =IF(B11="",0,IF(ISNUMBER(FIND($D11,J$5)),1,0)) -> 1 | K11: =IF(B11="",0,IF(ISNUMBER(FIND($D11,K$5)),1,0)) -> 0
A12: Hire talent | B12: hire | C12: word | D12: =" "&B12&IF(C12="word"," ","") -> hire | E12: =IF(B12="",0,IF(ISNUMBER(FIND($D12,E$5)),1,0)) -> 0 | F12: =IF(B12="",0,IF(ISNUMBER(FIND($D12,F$5)),1,0)) -> 0 | G12: =IF(B12="",0,IF(ISNUMBER(FIND($D12,G$5)),1,0)) -> 1 | H12: =IF(B12="",0,IF(ISNUMBER(FIND($D12,H$5)),1,0)) -> 1 | I12: =IF(B12="",0,IF(ISNUMBER(FIND($D12,I$5)),1,0)) -> 0 | J12: =IF(B12="",0,IF(ISNUMBER(FIND($D12,J$5)),1,0)) -> 0 | K12: =IF(B12="",0,IF(ISNUMBER(FIND($D12,K$5)),1,0)) -> 0
A13: Generic contact | B13: contact | C13: word | D13: =" "&B13&IF(C13="word"," ","") -> contact | E13: =IF(B13="",0,IF(ISNUMBER(FIND($D13,E$5)),1,0)) -> 1 | F13: =IF(B13="",0,IF(ISNUMBER(FIND($D13,F$5)),1,0)) -> 1 | G13: =IF(B13="",0,IF(ISNUMBER(FIND($D13,G$5)),1,0)) -> 1 | H13: =IF(B13="",0,IF(ISNUMBER(FIND($D13,H$5)),1,0)) -> 0 | I13: =IF(B13="",0,IF(ISNUMBER(FIND($D13,I$5)),1,0)) -> 0 | J13: =IF(B13="",0,IF(ISNUMBER(FIND($D13,J$5)),1,0)) -> 0 | K13: =IF(B13="",0,IF(ISNUMBER(FIND($D13,K$5)),1,0)) -> 0
A14: Generic contact | B14: get in touch | C14: prefix | D14: =" "&B14&IF(C14="word"," ","") -> get in touch | E14: =IF(B14="",0,IF(ISNUMBER(FIND($D14,E$5)),1,0)) -> 0 | F14: =IF(B14="",0,IF(ISNUMBER(FIND($D14,F$5)),1,0)) -> 0 | G14: =IF(B14="",0,IF(ISNUMBER(FIND($D14,G$5)),1,0)) -> 0 | H14: =IF(B14="",0,IF(ISNUMBER(FIND($D14,H$5)),1,0)) -> 0 | I14: =IF(B14="",0,IF(ISNUMBER(FIND($D14,I$5)),1,0)) -> 1 | J14: =IF(B14="",0,IF(ISNUMBER(FIND($D14,J$5)),1,0)) -> 1 | K14: =IF(B14="",0,IF(ISNUMBER(FIND($D14,K$5)),1,0)) -> 1
A15: NDA-first trust | B15: nda | C15: word | D15: =" "&B15&IF(C15="word"," ","") -> nda | E15: =IF(B15="",0,IF(ISNUMBER(FIND($D15,E$5)),1,0)) -> 0 | F15: =IF(B15="",0,IF(ISNUMBER(FIND($D15,F$5)),1,0)) -> 0 | G15: =IF(B15="",0,IF(ISNUMBER(FIND($D15,G$5)),1,0)) -> 0 | H15: =IF(B15="",0,IF(ISNUMBER(FIND($D15,H$5)),1,0)) -> 0 | I15: =IF(B15="",0,IF(ISNUMBER(FIND($D15,I$5)),1,0)) -> 1 | J15: =IF(B15="",0,IF(ISNUMBER(FIND($D15,J$5)),1,0)) -> 0 | K15: =IF(B15="",0,IF(ISNUMBER(FIND($D15,K$5)),1,0)) -> 0
A16: Show proof | B16: portfolio | C16: word | D16: =" "&B16&IF(C16="word"," ","") -> portfolio | E16: =IF(B16="",0,IF(ISNUMBER(FIND($D16,E$5)),1,0)) -> 0 | F16: =IF(B16="",0,IF(ISNUMBER(FIND($D16,F$5)),1,0)) -> 0 | G16: =IF(B16="",0,IF(ISNUMBER(FIND($D16,G$5)),1,0)) -> 0 | H16: =IF(B16="",0,IF(ISNUMBER(FIND($D16,H$5)),1,0)) -> 1 | I16: =IF(B16="",0,IF(ISNUMBER(FIND($D16,I$5)),1,0)) -> 0 | J16: =IF(B16="",0,IF(ISNUMBER(FIND($D16,J$5)),1,0)) -> 0 | K16: =IF(B16="",0,IF(ISNUMBER(FIND($D16,K$5)),1,0)) -> 0
A17: Show proof | B17: case stud | C17: prefix | D17: =" "&B17&IF(C17="word"," ","") -> case stud | E17: =IF(B17="",0,IF(ISNUMBER(FIND($D17,E$5)),1,0)) -> 0 | F17: =IF(B17="",0,IF(ISNUMBER(FIND($D17,F$5)),1,0)) -> 0 | G17: =IF(B17="",0,IF(ISNUMBER(FIND($D17,G$5)),1,0)) -> 0 | H17: =IF(B17="",0,IF(ISNUMBER(FIND($D17,H$5)),1,0)) -> 0 | I17: =IF(B17="",0,IF(ISNUMBER(FIND($D17,I$5)),1,0)) -> 1 | J17: =IF(B17="",0,IF(ISNUMBER(FIND($D17,J$5)),1,0)) -> 1 | K17: =IF(B17="",0,IF(ISNUMBER(FIND($D17,K$5)),1,0)) -> 0
... A20: Event / webinar | B20: register | C20: word | D20: =" "&B20&IF(C20="word"," ","") -> register | E20: =IF(B20="",0,IF(ISNUMBER(FIND($D20,E$5)),1,0)) -> 1 | F20: =IF(B20="",0,IF(ISNUMBER(FIND($D20,F$5)),1,0)) -> 0 | G20: =IF(B20="",0,IF(ISNUMBER(FIND($D20,G$5)),1,0)) -> 0 | H20: =IF(B20="",0,IF(ISNUMBER(FIND($D20,H$5)),1,0)) -> 0 | I20: =IF(B20="",0,IF(ISNUMBER(FIND($D20,I$5)),1,0)) -> 0 | J20: =IF(B20="",0,IF(ISNUMBER(FIND($D20,J$5)),1,0)) -> 0 | K20: =IF(B20="",0,IF(ISNUMBER(FIND($D20,K$5)),1,0)) -> 0
A22: Theme summary (1 = present) | D22: Brands using | E22: Simform | F22: Appinventiv | G22: Hyperlink InfoSystem | H22: Space-O (healthcare site) | I22: Intellectsoft | J22: Netguru | K22: Thoughtworks
A23: Book a call / consult | D23: =SUM(E23:K23) -> 5 | E23: =IF(SUMIF($A$6:$A$20,$A23,E$6:E$20)>0,1,0) -> 1 | F23: =IF(SUMIF($A$6:$A$20,$A23,F$6:F$20)>0,1,0) -> 1 | G23: =IF(SUMIF($A$6:$A$20,$A23,G$6:G$20)>0,1,0) -> 1 | H23: =IF(SUMIF($A$6:$A$20,$A23,H$6:H$20)>0,1,0) -> 1 | I23: =IF(SUMIF($A$6:$A$20,$A23,I$6:I$20)>0,1,0) -> 1 | J23: =IF(SUMIF($A$6:$A$20,$A23,J$6:J$20)>0,1,0) -> 0 | K23: =IF(SUMIF($A$6:$A$20,$A23,K$6:K$20)>0,1,0) -> 0
A24: Get a quote / estimate | D24: =SUM(E24:K24) -> 3 | E24: =IF(SUMIF($A$6:$A$20,$A24,E$6:E$20)>0,1,0) -> 0 | F24: =IF(SUMIF($A$6:$A$20,$A24,F$6:F$20)>0,1,0) -> 0 | G24: =IF(SUMIF($A$6:$A$20,$A24,G$6:G$20)>0,1,0) -> 1 | H24: =IF(SUMIF($A$6:$A$20,$A24,H$6:H$20)>0,1,0) -> 0 | I24: =IF(SUMIF($A$6:$A$20,$A24,I$6:I$20)>0,1,0) -> 1 | J24: =IF(SUMIF($A$6:$A$20,$A24,J$6:J$20)>0,1,0) -> 1 | K24: =IF(SUMIF($A$6:$A$20,$A24,K$6:K$20)>0,1,0) -> 0
A25: Hire talent | D25: =SUM(E25:K25) -> 2 | E25: =IF(SUMIF($A$6:$A$20,$A25,E$6:E$20)>0,1,0) -> 0 | F25: =IF(SUMIF($A$6:$A$20,$A25,F$6:F$20)>0,1,0) -> 0 | G25: =IF(SUMIF($A$6:$A$20,$A25,G$6:G$20)>0,1,0) -> 1 | H25: =IF(SUMIF($A$6:$A$20,$A25,H$6:H$20)>0,1,0) -> 1 | I25: =IF(SUMIF($A$6:$A$20,$A25,I$6:I$20)>0,1,0) -> 0 | J25: =IF(SUMIF($A$6:$A$20,$A25,J$6:J$20)>0,1,0) -> 0 | K25: =IF(SUMIF($A$6:$A$20,$A25,K$6:K$20)>0,1,0) -> 0
A26: Generic contact | D26: =SUM(E26:K26) -> 6 | E26: =IF(SUMIF($A$6:$A$20,$A26,E$6:E$20)>0,1,0) -> 1 | F26: =IF(SUMIF($A$6:$A$20,$A26,F$6:F$20)>0,1,0) -> 1 | G26: =IF(SUMIF($A$6:$A$20,$A26,G$6:G$20)>0,1,0) -> 1 | H26: =IF(SUMIF($A$6:$A$20,$A26,H$6:H$20)>0,1,0) -> 0 | I26: =IF(SUMIF($A$6:$A$20,$A26,I$6:I$20)>0,1,0) -> 1 | J26: =IF(SUMIF($A$6:$A$20,$A26,J$6:J$20)>0,1,0) -> 1 | K26: =IF(SUMIF($A$6:$A$20,$A26,K$6:K$20)>0,1,0) -> 1
A27: NDA-first trust | D27: =SUM(E27:K27) -> 1 | E27: =IF(SUMIF($A$6:$A$20,$A27,E$6:E$20)>0,1,0) -> 0 | F27: =IF(SUMIF($A$6:$A$20,$A27,F$6:F$20)>0,1,0) -> 0 | G27: =IF(SUMIF($A$6:$A$20,$A27,G$6:G$20)>0,1,0) -> 0 | H27: =IF(SUMIF($A$6:$A$20,$A27,H$6:H$20)>0,1,0) -> 0 | I27: =IF(SUMIF($A$6:$A$20,$A27,I$6:I$20)>0,1,0) -> 1 | J27: =IF(SUMIF($A$6:$A$20,$A27,J$6:J$20)>0,1,0) -> 0 | K27: =IF(SUMIF($A$6:$A$20,$A27,K$6:K$20)>0,1,0) -> 0
A28: Show proof | D28: =SUM(E28:K28) -> 4 | E28: =IF(SUMIF($A$6:$A$20,$A28,E$6:E$20)>0,1,0) -> 0 | F28: =IF(SUMIF($A$6:$A$20,$A28,F$6:F$20)>0,1,0) -> 0 | G28: =IF(SUMIF($A$6:$A$20,$A28,G$6:G$20)>0,1,0) -> 0 | H28: =IF(SUMIF($A$6:$A$20,$A28,H$6:H$20)>0,1,0) -> 1 | I28: =IF(SUMIF($A$6:$A$20,$A28,I$6:I$20)>0,1,0) -> 1 | J28: =IF(SUMIF($A$6:$A$20,$A28,J$6:J$20)>0,1,0) -> 1 | K28: =IF(SUMIF($A$6:$A$20,$A28,K$6:K$20)>0,1,0) -> 1
A29: Event / webinar | D29: =SUM(E29:K29) -> 1 | E29: =IF(SUMIF($A$6:$A$20,$A29,E$6:E$20)>0,1,0) -> 1 | F29: =IF(SUMIF($A$6:$A$20,$A29,F$6:F$20)>0,1,0) -> 0 | G29: =IF(SUMIF($A$6:$A$20,$A29,G$6:G$20)>0,1,0) -> 0 | H29: =IF(SUMIF($A$6:$A$20,$A29,H$6:H$20)>0,1,0) -> 0 | I29: =IF(SUMIF($A$6:$A$20,$A29,I$6:I$20)>0,1,0) -> 0 | J29: =IF(SUMIF($A$6:$A$20,$A29,J$6:J$20)>0,1,0) -> 0 | K29: =IF(SUMIF($A$6:$A$20,$A29,K$6:K$20)>0,1,0) -> 0

Sheet Engagement
A1: Engagement models named on the homepage
A2: Text is lower-cased, punctuation replaced by spaces, padded with spaces. 'word' = whole word, 'prefix' = word starts with keyword. Edit the blue keywords to re-run.
A4: Theme | B4: Keyword | C4: Match | D4: Search needle | E4: Simform | F4: Appinventiv | G4: Hyperlink InfoSystem | H4: Space-O (healthcare site) | I4: Intellectsoft | J4: Netguru | K4: Thoughtworks
A5: Normalised text | E5: =" "&SUBSTITUTE(SUBSTITUTE(SUBSTITUTE(SUBSTITUTE(SUBSTITUTE(SUBSTITUTE(SUBSTITUTE(SUBSTITUTE(SUBSTITUTE(SUBSTITUTE(SUBSTITUTE(SUBSTITUTE(SUBSTITUTE(SUBSTITUTE(SUBSTITUTE(SUBSTITUTE(LOWER(Brands!$G$2),"-"," "),"."," "),","," "),":"," "),";"," "),"!"," "),"?"," "),"'"," "),""""," "),"’"," "),"—"," "),"/"," "),"("," "),")"," "),"&"," "),"+"," ")&" " -> services as software outcome aligned commercials | F5: =" "&SUBSTITUTE(SUBSTITUTE(SUBSTITUTE(SUBSTITUTE(SUBSTITUTE(SUBSTITUTE(SUBSTITUTE(SUBSTITUTE(SUBSTITUTE(SUBSTITUTE(SUBSTITUTE(SUBSTITUTE(SUBSTITUTE(SUBSTITUTE(SUBSTITUTE(SUBSTITUTE(LOWER(Brands!$G$3),"-"," "),"."," "),","," "),":"," "),";"," "),"!"," "),"?"," "),"'"," "),""""," "),"’"," "),"—"," "),"/"," "),"("," "),")"," "),"&"," "),"+"," ")&" " -> dedicated development team it outsourcing offshore software development managed it services | G5: =" "&SUBSTITUTE(SUBSTITUTE(SUBSTITUTE(SUBSTITUTE(SUBSTITUTE(SUBSTITUTE(SUBSTITUTE(SUBSTITUTE(SUBSTITUTE(SUBSTITUTE(SUBSTITUTE(SUBSTITUTE(SUBSTITUTE(SUBSTITUTE(SUBSTITUTE(SUBSTITUTE(LOWER(Brands!$G$4),"-"," "),"."," "),","," "),":"," "),";"," "),"!"," "),"?"," "),"'"," "),""""," "),"’"," "),"—"," "),"/"," "),"("," "),")"," "),"&"," "),"+"," ")&" " -> fixed price model hire dedicated model hourly rate onsite model contract basis | H5: =" "&SUBSTITUTE(SUBSTITUTE(SUBSTITUTE(SUBSTITUTE(SUBSTITUTE(SUBSTITUTE(SUBSTITUTE(SUBSTITUTE(SUBSTITUTE(SUBSTITUTE(SUBSTITUTE(SUBSTITUTE(SUBSTITUTE(SUBSTITUTE(SUBSTITUTE(SUBSTITUTE(LOWER(Brands!$G$5),"-"," "),"."," "),","," "),":"," "),";"," "),"!"," "),"?"," "),"'"," "),""""," "),"’"," "),"—"," "),"/"," "),"("," "),")"," "),"&"," "),"+"," ")&" " -> fixed scope healthcare projects milestone based payment 20 50% upfront dedicated healthcare development team 3 15 specialists staff augmentation for healthcare engineering custom pricing | I5: =" "&SUBSTITUTE(SUBSTITUTE(SUBSTITUTE(SUBSTITUTE(SUBSTITUTE(SUBSTITUTE(SUBSTITUTE(SUBSTITUTE(SUBSTITUTE(SUBSTITUTE(SUBSTITUTE(SUBSTITUTE(SUBSTITUTE(SUBSTITUTE(SUBSTITUTE(SUBSTITUTE(LOWER(Brands!$G$6),"-"," "),"."," "),","," "),":"," "),";"," "),"!"," "),"?"," "),"'"," "),""""," "),"’"," "),"—"," "),"/"," "),"("," "),")"," "),"&"," "),"+"," ")&" " -> dedicated development teams staff augmentation team extension mvp development outsourcing nearshore | J5: =" "&SUBSTITUTE(SUBSTITUTE(SUBSTITUTE(SUBSTITUTE(SUBSTITUTE(SUBSTITUTE(SUBSTITUTE(SUBSTITUTE(SUBSTITUTE(SUBSTITUTE(SUBSTITUTE(SUBSTITUTE(SUBSTITUTE(SUBSTITUTE(SUBSTITUTE(SUBSTITUTE(LOWER(Brands!$G$7),"-"," "),"."," "),","," "),":"," "),";"," "),"!"," "),"?"," "),"'"," "),""""," "),"’"," "),"—"," "),"/"," "),"("," "),")"," "),"&"," "),"+"," ")&" " -> dedicated teams staff augmentation delivery center | K5: =" "&SUBSTITUTE(SUBSTITUTE(SUBSTITUTE(SUBSTITUTE(SUBSTITUTE(SUBSTITUTE(SUBSTITUTE(SUBSTITUTE(SUBSTITUTE(SUBSTITUTE(SUBSTITUTE(SUBSTITUTE(SUBSTITUTE(SUBSTITUTE(SUBSTITUTE(SUBSTITUTE(LOWER(Brands!$G$8),"-"," "),"."," "),","," "),":"," "),";"," "),"!"," "),"?"," "),"'"," "),""""," "),"’"," "),"—"," "),"/"," "),"("," "),")"," "),"&"," "),"+"," ")&" "
A6: Fixed price | B6: fixed | C6: word | D6: =" "&B6&IF(C6="word"," ","") -> fixed | E6: =IF(B6="",0,IF(ISNUMBER(FIND($D6,E$5)),1,0)) -> 0 | F6: =IF(B6="",0,IF(ISNUMBER(FIND($D6,F$5)),1,0)) -> 0 | G6: =IF(B6="",0,IF(ISNUMBER(FIND($D6,G$5)),1,0)) -> 1 | H6: =IF(B6="",0,IF(ISNUMBER(FIND($D6,H$5)),1,0)) -> 1 | I6: =IF(B6="",0,IF(ISNUMBER(FIND($D6,I$5)),1,0)) -> 0 | J6: =IF(B6="",0,IF(ISNUMBER(FIND($D6,J$5)),1,0)) -> 0 | K6: =IF(B6="",0,IF(ISNUMBER(FIND($D6,K$5)),1,0)) -> 0
A7: Hourly / T&M | B7: hourly | C7: word | D7: =" "&B7&IF(C7="word"," ","") -> hourly | E7: =IF(B7="",0,IF(ISNUMBER(FIND($D7,E$5)),1,0)) -> 0 | F7: =IF(B7="",0,IF(ISNUMBER(FIND($D7,F$5)),1,0)) -> 0 | G7: =IF(B7="",0,IF(ISNUMBER(FIND($D7,G$5)),1,0)) -> 1 | H7: =IF(B7="",0,IF(ISNUMBER(FIND($D7,H$5)),1,0)) -> 0 | I7: =IF(B7="",0,IF(ISNUMBER(FIND($D7,I$5)),1,0)) -> 0 | J7: =IF(B7="",0,IF(ISNUMBER(FIND($D7,J$5)),1,0)) -> 0 | K7: =IF(B7="",0,IF(ISNUMBER(FIND($D7,K$5)),1,0)) -> 0
A8: Dedicated team | B8: dedicated | C8: word | D8: =" "&B8&IF(C8="word"," ","") -> dedicated | E8: =IF(B8="",0,IF(ISNUMBER(FIND($D8,E$5)),1,0)) -> 0 | F8: =IF(B8="",0,IF(ISNUMBER(FIND($D8,F$5)),1,0)) -> 1 | G8: =IF(B8="",0,IF(ISNUMBER(FIND($D8,G$5)),1,0)) -> 1 | H8: =IF(B8="",0,IF(ISNUMBER(FIND($D8,H$5)),1,0)) -> 1 | I8: =IF(B8="",0,IF(ISNUMBER(FIND($D8,I$5)),1,0)) -> 1 | J8: =IF(B8="",0,IF(ISNUMBER(FIND($D8,J$5)),1,0)) -> 1 | K8: =IF(B8="",0,IF(ISNUMBER(FIND($D8,K$5)),1,0)) -> 0
A9: Staff augmentation | B9: staff augmentation | C9: prefix | D9: =" "&B9&IF(C9="word"," ","") -> staff augmentation | E9: =IF(B9="",0,IF(ISNUMBER(FIND($D9,E$5)),1,0)) -> 0 | F9: =IF(B9="",0,IF(ISNUMBER(FIND($D9,F$5)),1,0)) -> 0 | G9: =IF(B9="",0,IF(ISNUMBER(FIND($D9,G$5)),1,0)) -> 0 | H9: =IF(B9="",0,IF(ISNUMBER(FIND($D9,H$5)),1,0)) -> 1 | I9: =IF(B9="",0,IF(ISNUMBER(FIND($D9,I$5)),1,0)) -> 1 | J9: =IF(B9="",0,IF(ISNUMBER(FIND($D9,J$5)),1,0)) -> 1 | K9: =IF(B9="",0,IF(ISNUMBER(FIND($D9,K$5)),1,0)) -> 0
A10: Staff augmentation | B10: team extension | C10: prefix | D10: =" "&B10&IF(C10="word"," ","") -> team extension | E10: =IF(B10="",0,IF(ISNUMBER(FIND($D10,E$5)),1,0)) -> 0 | F10: =IF(B10="",0,IF(ISNUMBER(FIND($D10,F$5)),1,0)) -> 0 | G10: =IF(B10="",0,IF(ISNUMBER(FIND($D10,G$5)),1,0)) -> 0 | H10: =IF(B10="",0,IF(ISNUMBER(FIND($D10,H$5)),1,0)) -> 0 | I10: =IF(B10="",0,IF(ISNUMBER(FIND($D10,I$5)),1,0)) -> 1 | J10: =IF(B10="",0,IF(ISNUMBER(FIND($D10,J$5)),1,0)) -> 0 | K10: =IF(B10="",0,IF(ISNUMBER(FIND($D10,K$5)),1,0)) -> 0
A11: Outcome-based | B11: outcome | C11: prefix | D11: =" "&B11&IF(C11="word"," ","") -> outcome | E11: =IF(B11="",0,IF(ISNUMBER(FIND($D11,E$5)),1,0)) -> 1 | F11: =IF(B11="",0,IF(ISNUMBER(FIND($D11,F$5)),1,0)) -> 0 | G11: =IF(B11="",0,IF(ISNUMBER(FIND($D11,G$5)),1,0)) -> 0 | H11: =IF(B11="",0,IF(ISNUMBER(FIND($D11,H$5)),1,0)) -> 0 | I11: =IF(B11="",0,IF(ISNUMBER(FIND($D11,I$5)),1,0)) -> 0 | J11: =IF(B11="",0,IF(ISNUMBER(FIND($D11,J$5)),1,0)) -> 0 | K11: =IF(B11="",0,IF(ISNUMBER(FIND($D11,K$5)),1,0)) -> 0
A12: Outsourcing / offshore | B12: outsourcing | C12: word | D12: =" "&B12&IF(C12="word"," ","") -> outsourcing | E12: =IF(B12="",0,IF(ISNUMBER(FIND($D12,E$5)),1,0)) -> 0 | F12: =IF(B12="",0,IF(ISNUMBER(FIND($D12,F$5)),1,0)) -> 1 | G12: =IF(B12="",0,IF(ISNUMBER(FIND($D12,G$5)),1,0)) -> 0 | H12: =IF(B12="",0,IF(ISNUMBER(FIND($D12,H$5)),1,0)) -> 0 | I12: =IF(B12="",0,IF(ISNUMBER(FIND($D12,I$5)),1,0)) -> 1 | J12: =IF(B12="",0,IF(ISNUMBER(FIND($D12,J$5)),1,0)) -> 0 | K12: =IF(B12="",0,IF(ISNUMBER(FIND($D12,K$5)),1,0)) -> 0
A13: Outsourcing / offshore | B13: offshore | C13: word | D13: =" "&B13&IF(C13="word"," ","") -> offshore | E13: =IF(B13="",0,IF(ISNUMBER(FIND($D13,E$5)),1,0)) -> 0 | F13: =IF(B13="",0,IF(ISNUMBER(FIND($D13,F$5)),1,0)) -> 1 | G13: =IF(B13="",0,IF(ISNUMBER(FIND($D13,G$5)),1,0)) -> 0 | H13: =IF(B13="",0,IF(ISNUMBER(FIND($D13,H$5)),1,0)) -> 0 | I13: =IF(B13="",0,IF(ISNUMBER(FIND($D13,I$5)),1,0)) -> 0 | J13: =IF(B13="",0,IF(ISNUMBER(FIND($D13,J$5)),1,0)) -> 0 | K13: =IF(B13="",0,IF(ISNUMBER(FIND($D13,K$5)),1,0)) -> 0
A14: Outsourcing / offshore | B14: nearshore | C14: word | D14: =" "&B14&IF(C14="word"," ","") -> nearshore | E14: =IF(B14="",0,IF(ISNUMBER(FIND($D14,E$5)),1,0)) -> 0 | F14: =IF(B14="",0,IF(ISNUMBER(FIND($D14,F$5)),1,0)) -> 0 | G14: =IF(B14="",0,IF(ISNUMBER(FIND($D14,G$5)),1,0)) -> 0 | H14: =IF(B14="",0,IF(ISNUMBER(FIND($D14,H$5)),1,0)) -> 0 | I14: =IF(B14="",0,IF(ISNUMBER(FIND($D14,I$5)),1,0)) -> 1 | J14: =IF(B14="",0,IF(ISNUMBER(FIND($D14,J$5)),1,0)) -> 0 | K14: =IF(B14="",0,IF(ISNUMBER(FIND($D14,K$5)),1,0)) -> 0
A15: Managed services | B15: managed | C15: word | D15: =" "&B15&IF(C15="word"," ","") -> managed | E15: =IF(B15="",0,IF(ISNUMBER(FIND($D15,E$5)),1,0)) -> 0 | F15: =IF(B15="",0,IF(ISNUMBER(FIND($D15,F$5)),1,0)) -> 1 | G15: =IF(B15="",0,IF(ISNUMBER(FIND($D15,G$5)),1,0)) -> 0 | H15: =IF(B15="",0,IF(ISNUMBER(FIND($D15,H$5)),1,0)) -> 0 | I15: =IF(B15="",0,IF(ISNUMBER(FIND($D15,I$5)),1,0)) -> 0 | J15: =IF(B15="",0,IF(ISNUMBER(FIND($D15,J$5)),1,0)) -> 0 | K15: =IF(B15="",0,IF(ISNUMBER(FIND($D15,K$5)),1,0)) -> 0
A17: Theme summary (1 = present) | D17: Brands using | E17: Simform | F17: Appinventiv | G17: Hyperlink InfoSystem | H17: Space-O (healthcare site) | I17: Intellectsoft | J17: Netguru | K17: Thoughtworks
A18: Fixed price | D18: =SUM(E18:K18) -> 2 | E18: =IF(SUMIF($A$6:$A$15,$A18,E$6:E$15)>0,1,0) -> 0 | F18: =IF(SUMIF($A$6:$A$15,$A18,F$6:F$15)>0,1,0) -> 0 | G18: =IF(SUMIF($A$6:$A$15,$A18,G$6:G$15)>0,1,0) -> 1 | H18: =IF(SUMIF($A$6:$A$15,$A18,H$6:H$15)>0,1,0) -> 1 | I18: =IF(SUMIF($A$6:$A$15,$A18,I$6:I$15)>0,1,0) -> 0 | J18: =IF(SUMIF($A$6:$A$15,$A18,J$6:J$15)>0,1,0) -> 0 | K18: =IF(SUMIF($A$6:$A$15,$A18,K$6:K$15)>0,1,0) -> 0
A19: Hourly / T&M | D19: =SUM(E19:K19) -> 1 | E19: =IF(SUMIF($A$6:$A$15,$A19,E$6:E$15)>0,1,0) -> 0 | F19: =IF(SUMIF($A$6:$A$15,$A19,F$6:F$15)>0,1,0) -> 0 | G19: =IF(SUMIF($A$6:$A$15,$A19,G$6:G$15)>0,1,0) -> 1 | H19: =IF(SUMIF($A$6:$A$15,$A19,H$6:H$15)>0,1,0) -> 0 | I19: =IF(SUMIF($A$6:$A$15,$A19,I$6:I$15)>0,1,0) -> 0 | J19: =IF(SUMIF($A$6:$A$15,$A19,J$6:J$15)>0,1,0) -> 0 | K19: =IF(SUMIF($A$6:$A$15,$A19,K$6:K$15)>0,1,0) -> 0
A20: Dedicated team | D20: =SUM(E20:K20) -> 5 | E20: =IF(SUMIF($A$6:$A$15,$A20,E$6:E$15)>0,1,0) -> 0 | F20: =IF(SUMIF($A$6:$A$15,$A20,F$6:F$15)>0,1,0) -> 1 | G20: =IF(SUMIF($A$6:$A$15,$A20,G$6:G$15)>0,1,0) -> 1 | H20: =IF(SUMIF($A$6:$A$15,$A20,H$6:H$15)>0,1,0) -> 1 | I20: =IF(SUMIF($A$6:$A$15,$A20,I$6:I$15)>0,1,0) -> 1 | J20: =IF(SUMIF($A$6:$A$15,$A20,J$6:J$15)>0,1,0) -> 1 | K20: =IF(SUMIF($A$6:$A$15,$A20,K$6:K$15)>0,1,0) -> 0
A21: Staff augmentation | D21: =SUM(E21:K21) -> 3 | E21: =IF(SUMIF($A$6:$A$15,$A21,E$6:E$15)>0,1,0) -> 0 | F21: =IF(SUMIF($A$6:$A$15,$A21,F$6:F$15)>0,1,0) -> 0 | G21: =IF(SUMIF($A$6:$A$15,$A21,G$6:G$15)>0,1,0) -> 0 | H21: =IF(SUMIF($A$6:$A$15,$A21,H$6:H$15)>0,1,0) -> 1 | I21: =IF(SUMIF($A$6:$A$15,$A21,I$6:I$15)>0,1,0) -> 1 | J21: =IF(SUMIF($A$6:$A$15,$A21,J$6:J$15)>0,1,0) -> 1 | K21: =IF(SUMIF($A$6:$A$15,$A21,K$6:K$15)>0,1,0) -> 0
A22: Outcome-based | D22: =SUM(E22:K22) -> 1 | E22: =IF(SUMIF($A$6:$A$15,$A22,E$6:E$15)>0,1,0) -> 1 | F22: =IF(SUMIF($A$6:$A$15,$A22,F$6:F$15)>0,1,0) -> 0 | G22: =IF(SUMIF($A$6:$A$15,$A22,G$6:G$15)>0,1,0) -> 0 | H22: =IF(SUMIF($A$6:$A$15,$A22,H$6:H$15)>0,1,0) -> 0 | I22: =IF(SUMIF($A$6:$A$15,$A22,I$6:I$15)>0,1,0) -> 0 | J22: =IF(SUMIF($A$6:$A$15,$A22,J$6:J$15)>0,1,0) -> 0 | K22: =IF(SUMIF($A$6:$A$15,$A22,K$6:K$15)>0,1,0) -> 0
A23: Outsourcing / offshore | D23: =SUM(E23:K23) -> 2 | E23: =IF(SUMIF($A$6:$A$15,$A23,E$6:E$15)>0,1,0) -> 0 | F23: =IF(SUMIF($A$6:$A$15,$A23,F$6:F$15)>0,1,0) -> 1 | G23: =IF(SUMIF($A$6:$A$15,$A23,G$6:G$15)>0,1,0) -> 0 | H23: =IF(SUMIF($A$6:$A$15,$A23,H$6:H$15)>0,1,0) -> 0 | I23: =IF(SUMIF($A$6:$A$15,$A23,I$6:I$15)>0,1,0) -> 1 | J23: =IF(SUMIF($A$6:$A$15,$A23,J$6:J$15)>0,1,0) -> 0 | K23: =IF(SUMIF($A$6:$A$15,$A23,K$6:K$15)>0,1,0) -> 0
A24: Managed services | D24: =SUM(E24:K24) -> 1 | E24: =IF(SUMIF($A$6:$A$15,$A24,E$6:E$15)>0,1,0) -> 0 | F24: =IF(SUMIF($A$6:$A$15,$A24,F$6:F$15)>0,1,0) -> 1 | G24: =IF(SUMIF($A$6:$A$15,$A24,G$6:G$15)>0,1,0) -> 0 | H24: =IF(SUMIF($A$6:$A$15,$A24,H$6:H$15)>0,1,0) -> 0 | I24: =IF(SUMIF($A$6:$A$15,$A24,I$6:I$15)>0,1,0) -> 0 | J24: =IF(SUMIF($A$6:$A$15,$A24,J$6:J$15)>0,1,0) -> 0 | K24: =IF(SUMIF($A$6:$A$15,$A24,K$6:K$15)>0,1,0) -> 0

Sheet Metrics
A1: Per-brand metrics (formulas on Brands sheet)
A3: Brand | B3: Industries listed | C3: Engagement models named | D3: CTAs listed | E3: Partner badges | F3: Compliance items listed | G3: Content engine score (0-6) | H3: Publishes a rate | I3: Years claimed | J3: Team claimed
A4: =Brands!$A$2 -> Simform | B4: =IF(Brands!$F$2="",0,LEN(Brands!$F$2)-LEN(SUBSTITUTE(Brands!$F$2,";",""))+1) -> 5 | C4: =IF(Brands!$G$2="",0,LEN(Brands!$G$2)-LEN(SUBSTITUTE(Brands!$G$2,";",""))+1) -> 1 | D4: =IF(Brands!$K$2="",0,LEN(Brands!$K$2)-LEN(SUBSTITUTE(Brands!$K$2,";",""))+1) -> 4 | E4: =IF(Brands!$P$2="",0,LEN(Brands!$P$2)-LEN(SUBSTITUTE(Brands!$P$2,";",""))+1) -> 10 | F4: =IF(Brands!$Q$2="",0,LEN(Brands!$Q$2)-LEN(SUBSTITUTE(Brands!$Q$2,";",""))+1) -> 1 | G4: =IF(Brands!$S$2="Yes",1,IF(Brands!$S$2="Partial",0.5,0))+IF(Brands!$T$2="Yes",1,IF(Brands!$T$2="Partial",0.5,0))+IF(Brands!$U$2="Yes",1,IF(Brands!$U$2="Partial",0.5,0))+IF(Brands!$V$2="Yes",1,IF(Brands!$V$2="Partial",0.5,0))+IF(Brands!$W$2="Yes",1,IF(Brands!$W$2="Partial",0.5,0))+IF(Brands!$X$2="Yes",1,IF(Brands!$X$2="Partial",0.5,0)) -> 6 | H4: =IF(Brands!$I$2="","No","Yes") -> No | I4: =IF(Brands!$L$2="","",Brands!$L$2) | J4: =IF(Brands!$M$2="","",Brands!$M$2)
A5: =Brands!$A$3 -> Appinventiv | B5: =IF(Brands!$F$3="",0,LEN(Brands!$F$3)-LEN(SUBSTITUTE(Brands!$F$3,";",""))+1) -> 31 | C5: =IF(Brands!$G$3="",0,LEN(Brands!$G$3)-LEN(SUBSTITUTE(Brands!$G$3,";",""))+1) -> 4 | D5: =IF(Brands!$K$3="",0,LEN(Brands!$K$3)-LEN(SUBSTITUTE(Brands!$K$3,";",""))+1) -> 6 | E5: =IF(Brands!$P$3="",0,LEN(Brands!$P$3)-LEN(SUBSTITUTE(Brands!$P$3,";",""))+1) -> 3 | F5: =IF(Brands!$Q$3="",0,LEN(Brands!$Q$3)-LEN(SUBSTITUTE(Brands!$Q$3,";",""))+1) -> 15 | G5: =IF(Brands!$S$3="Yes",1,IF(Brands!$S$3="Partial",0.5,0))+IF(Brands!$T$3="Yes",1,IF(Brands!$T$3="Partial",0.5,0))+IF(Brands!$U$3="Yes",1,IF(Brands!$U$3="Partial",0.5,0))+IF(Brands!$V$3="Yes",1,IF(Brands!$V$3="Partial",0.5,0))+IF(Brands!$W$3="Yes",1,IF(Brands!$W$3="Partial",0.5,0))+IF(Brands!$X$3="Yes",1,IF(Brands!$X$3="Partial",0.5,0)) -> 4 | H5: =IF(Brands!$I$3="","No","Yes") -> No | I5: =IF(Brands!$L$3="","",Brands!$L$3) -> 11 | J5: =IF(Brands!$M$3="","",Brands!$M$3) -> 1700
A6: =Brands!$A$4 -> Hyperlink InfoSystem | B6: =IF(Brands!$F$4="",0,LEN(Brands!$F$4)-LEN(SUBSTITUTE(Brands!$F$4,";",""))+1) -> 13 | C6: =IF(Brands!$G$4="",0,LEN(Brands!$G$4)-LEN(SUBSTITUTE(Brands!$G$4,";",""))+1) -> 3 | D6: =IF(Brands!$K$4="",0,LEN(Brands!$K$4)-LEN(SUBSTITUTE(Brands!$K$4,";",""))+1) -> 7 | E6: =IF(Brands!$P$4="",0,LEN(Brands!$P$4)-LEN(SUBSTITUTE(Brands!$P$4,";",""))+1) -> 4 | F6: =IF(Brands!$Q$4="",0,LEN(Brands!$Q$4)-LEN(SUBSTITUTE(Brands!$Q$4,";",""))+1) -> 1 | G6: =IF(Brands!$S$4="Yes",1,IF(Brands!$S$4="Partial",0.5,0))+IF(Brands!$T$4="Yes",1,IF(Brands!$T$4="Partial",0.5,0))+IF(Brands!$U$4="Yes",1,IF(Brands!$U$4="Partial",0.5,0))+IF(Brands!$V$4="Yes",1,IF(Brands!$V$4="Partial",0.5,0))+IF(Brands!$W$4="Yes",1,IF(Brands!$W$4="Partial",0.5,0))+IF(Brands!$X$4="Yes",1,IF(Brands!$X$4="Partial",0.5,0)) -> 6 | H6: =IF(Brands!$I$4="","No","Yes") -> No | I6: =IF(Brands!$L$4="","",Brands!$L$4) -> 14 | J6: =IF(Brands!$M$4="","",Brands!$M$4) -> 1200
A7: =Brands!$A$5 -> Space-O (healthcare site) | B7: =IF(Brands!$F$5="",0,LEN(Brands!$F$5)-LEN(SUBSTITUTE(Brands!$F$5,";",""))+1) -> 4 | C7: =IF(Brands!$G$5="",0,LEN(Brands!$G$5)-LEN(SUBSTITUTE(Brands!$G$5,";",""))+1) -> 3 | D7: =IF(Brands!$K$5="",0,LEN(Brands!$K$5)-LEN(SUBSTITUTE(Brands!$K$5,";",""))+1) -> 5 | E7: =IF(Brands!$P$5="",0,LEN(Brands!$P$5)-LEN(SUBSTITUTE(Brands!$P$5,";",""))+1) -> 3 | F7: =IF(Brands!$Q$5="",0,LEN(Brands!$Q$5)-LEN(SUBSTITUTE(Brands!$Q$5,";",""))+1) -> 5 | G7: =IF(Brands!$S$5="Yes",1,IF(Brands!$S$5="Partial",0.5,0))+IF(Brands!$T$5="Yes",1,IF(Brands!$T$5="Partial",0.5,0))+IF(Brands!$U$5="Yes",1,IF(Brands!$U$5="Partial",0.5,0))+IF(Brands!$V$5="Yes",1,IF(Brands!$V$5="Partial",0.5,0))+IF(Brands!$W$5="Yes",1,IF(Brands!$W$5="Partial",0.5,0))+IF(Brands!$X$5="Yes",1,IF(Brands!$X$5="Partial",0.5,0)) -> 3 | H7: =IF(Brands!$I$5="","No","Yes") -> Yes | I7: =IF(Brands!$L$5="","",Brands!$L$5) | J7: =IF(Brands!$M$5="","",Brands!$M$5) -> 50
A8: =Brands!$A$6 -> Intellectsoft | B8: =IF(Brands!$F$6="",0,LEN(Brands!$F$6)-LEN(SUBSTITUTE(Brands!$F$6,";",""))+1) -> 7 | C8: =IF(Brands!$G$6="",0,LEN(Brands!$G$6)-LEN(SUBSTITUTE(Brands!$G$6,";",""))+1) -> 6 | D8: =IF(Brands!$K$6="",0,LEN(Brands!$K$6)-LEN(SUBSTITUTE(Brands!$K$6,";",""))+1) -> 6 | E8: =IF(Brands!$P$6="",0,LEN(Brands!$P$6)-LEN(SUBSTITUTE(Brands!$P$6,";",""))+1) -> 5 | F8: =IF(Brands!$Q$6="",0,LEN(Brands!$Q$6)-LEN(SUBSTITUTE(Brands!$Q$6,";",""))+1) -> 4 | G8: =IF(Brands!$S$6="Yes",1,IF(Brands!$S$6="Partial",0.5,0))+IF(Brands!$T$6="Yes",1,IF(Brands!$T$6="Partial",0.5,0))+IF(Brands!$U$6="Yes",1,IF(Brands!$U$6="Partial",0.5,0))+IF(Brands!$V$6="Yes",1,IF(Brands!$V$6="Partial",0.5,0))+IF(Brands!$W$6="Yes",1,IF(Brands!$W$6="Partial",0.5,0))+IF(Brands!$X$6="Yes",1,IF(Brands!$X$6="Partial",0.5,0)) -> 4 | H8: =IF(Brands!$I$6="","No","Yes") -> No | I8: =IF(Brands!$L$6="","",Brands!$L$6) -> 19 | J8: =IF(Brands!$M$6="","",Brands!$M$6)
A9: =Brands!$A$7 -> Netguru | B9: =IF(Brands!$F$7="",0,LEN(Brands!$F$7)-LEN(SUBSTITUTE(Brands!$F$7,";",""))+1) -> 5 | C9: =IF(Brands!$G$7="",0,LEN(Brands!$G$7)-LEN(SUBSTITUTE(Brands!$G$7,";",""))+1) -> 3 | D9: =IF(Brands!$K$7="",0,LEN(Brands!$K$7)-LEN(SUBSTITUTE(Brands!$K$7,";",""))+1) -> 3 | E9: =IF(Brands!$P$7="",0,LEN(Brands!$P$7)-LEN(SUBSTITUTE(Brands!$P$7,";",""))+1) -> 4 | F9: =IF(Brands!$Q$7="",0,LEN(Brands!$Q$7)-LEN(SUBSTITUTE(Brands!$Q$7,";",""))+1) -> 2 | G9: =IF(Brands!$S$7="Yes",1,IF(Brands!$S$7="Partial",0.5,0))+IF(Brands!$T$7="Yes",1,IF(Brands!$T$7="Partial",0.5,0))+IF(Brands!$U$7="Yes",1,IF(Brands!$U$7="Partial",0.5,0))+IF(Brands!$V$7="Yes",1,IF(Brands!$V$7="Partial",0.5,0))+IF(Brands!$W$7="Yes",1,IF(Brands!$W$7="Partial",0.5,0))+IF(Brands!$X$7="Yes",1,IF(Brands!$X$7="Partial",0.5,0)) -> 5 | H9: =IF(Brands!$I$7="","No","Yes") -> No | I9: =IF(Brands!$L$7="","",Brands!$L$7) -> 17 | J9: =IF(Brands!$M$7="","",Brands!$M$7) -> 400
A10: =Brands!$A$8 -> Thoughtworks | B10: =IF(Brands!$F$8="",0,LEN(Brands!$F$8)-LEN(SUBSTITUTE(Brands!$F$8,";",""))+1) -> 11 | C10: =IF(Brands!$G$8="",0,LEN(Brands!$G$8)-LEN(SUBSTITUTE(Brands!$G$8,";",""))+1) -> 0 | D10: =IF(Brands!$K$8="",0,LEN(Brands!$K$8)-LEN(SUBSTITUTE(Brands!$K$8,";",""))+1) -> 5 | E10: =IF(Brands!$P$8="",0,LEN(Brands!$P$8)-LEN(SUBSTITUTE(Brands!$P$8,";",""))+1) -> 5 | F10: =IF(Brands!$Q$8="",0,LEN(Brands!$Q$8)-LEN(SUBSTITUTE(Brands!$Q$8,";",""))+1) -> 0 | G10: =IF(Brands!$S$8="Yes",1,IF(Brands!$S$8="Partial",0.5,0))+IF(Brands!$T$8="Yes",1,IF(Brands!$T$8="Partial",0.5,0))+IF(Brands!$U$8="Yes",1,IF(Brands!$U$8="Partial",0.5,0))+IF(Brands!$V$8="Yes",1,IF(Brands!$V$8="Partial",0.5,0))+IF(Brands!$W$8="Yes",1,IF(Brands!$W$8="Partial",0.5,0))+IF(Brands!$X$8="Yes",1,IF(Brands!$X$8="Partial",0.5,0)) -> 3.5 | H10: =IF(Brands!$I$8="","No","Yes") -> No | I10: =IF(Brands!$L$8="","",Brands!$L$8) | J10: =IF(Brands!$M$8="","",Brands!$M$8)
A12: Median industries listed | B12: =MEDIAN(B4:B10) -> 7
A13: Median content engine score | B13: =MEDIAN(G4:G10) -> 4
A14: Median partner badges | B14: =MEDIAN(E4:E10) -> 4

Sheet GTM Plan
A1: GTM recommendations derived from the data (hypotheses to test, not facts)
A2: Wingman Partners' own site could not be read; these are framed for a software-services firm of its type.
A4: Key number (live) | B4: Value
A5: Brands compared | B5: =COUNTA(Brands!$A$2:$A$8) -> 7
A6: Headlines AI-led | B6: =Positioning!$D$27 -> 7
A7: Headlines naming a vertical | B7: =Positioning!$D$32 -> 2
A8: Brands publishing a rate | B8: =COUNTIF(Metrics!$H$4:$H$10,"Yes") -> 1
A9: Call / consult CTA | B9: ='CTA Funnel'!$D$23 -> 5
